Workbook

Sheet COM
H4: 91.6 | J4: 88.4 | L4: 89.3 | N4: 89.5 | P4: 90 | R4: 90.5
A5: Классификация | E5: донор | F5: Наименование проекта | G5: номер и дата кредитного соглашения | H5: 2025 | J5: 2026 | L5: 2027 | N5: 2028 | P5: 2029 | R5: 2030
A6: III | B6: IV | D6: V | H6: Внутреннее | I6: Внешнее | J6: Внутреннее | K6: Внешнее | L6: Внутреннее | M6: Внешнее | N6: Внутреннее | O6: Внешнее | P6: Внутреннее | Q6: Внешнее | R6: Внутреннее | S6: Внешнее
F7: Министерство финансов КР | H7: =H8 -> #REF! | I7: =I8 -> #REF! | J7: =J8 -> #REF! | K7: =K8 -> #REF! | L7: =L8 -> #REF! | M7: =M8 -> #REF! | N7: =N8 -> #REF! | O7: =O8 -> #REF! | ... S7: =S8 -> #REF! | T7: =I7+K7+M7+O7+Q7+S7 -> #REF!
F8: Государственные инвестиции | H8: =SUM(H9:H38) -> #REF! | I8: =SUM(I9:I38) -> #REF! | J8: =SUM(J9:J38) -> #REF! | K8: =SUM(K9:K38) -> #REF! | L8: =SUM(L9:L38) -> #REF! | M8: =SUM(M9:M38) -> #REF! | N8: =SUM(N9:N38) -> #REF! | O8: =SUM(O9:O38) -> #REF! | ... S8: =SUM(S9:S38) -> #REF! | T8: =I8+K8+M8+O8+Q8+S8 -> #REF!
A9: 311 | B9: 25 | C9: 910 | D9: 70499 | F9: Цепочка добавленной стоимости агрофинансирования (КфВ) Фаза 2 | H9: =#REF!*COM!$H$4 -> #REF! | I9: =#REF!*COM!$H$4 -> #REF! | J9: =#REF!*COM!$J$4 -> #REF! | K9: =#REF!*COM!$J$4 -> #REF! | L9: =#REF!*COM!$L$4 -> #REF! | M9: =#REF!*COM!$L$4 -> #REF! | N9: =#REF!*COM!$N$4 -> #REF! | O9: =#REF!*COM!$N$4 -> #REF! | P9: =#REF!*COM!$P$4 -> #REF! | Q9: =#REF!*COM!$P$4 -> #REF! | R9: =#REF!*COM!$R$4 -> #REF! | S9: =#REF!*COM!$R$4 -> #REF! | T9: =I9+K9+M9+O9+Q9+S9 -> #REF!
A10: 311 | B10: 25 | C10: 920 | D10: 70499 | E10: КфВ | F10: Цепочка добавленной стоимости агрофинансирования (КфВ) (грант) Фаза 2 | H10: =#REF!*COM!$H$4 -> #REF! | I10: =#REF!*COM!$H$4 -> #REF! | J10: =#REF!*COM!$J$4 -> #REF! | K10: =#REF!*COM!$J$4 -> #REF! | L10: =#REF!*COM!$L$4 -> #REF! | M10: =#REF!*COM!$L$4 -> #REF! | N10: =#REF!*COM!$N$4 -> #REF! | O10: =#REF!*COM!$N$4 -> #REF! | P10: =#REF!*COM!$P$4 -> #REF! | Q10: =#REF!*COM!$P$4 -> #REF! | R10: =#REF!*COM!$R$4 -> #REF! | S10: =#REF!*COM!$R$4 -> #REF! | T10: =I10+K10+M10+O10+Q10+S10 -> #REF!
A11: 311 | B11: 25 | C11: 910 | D11: 70499 | F11: Цепочка добавленной стоимости агрофинансирования-2 (ИФЦА) | H11: =#REF!*COM!$H$4 -> #REF! | I11: =#REF!*COM!$H$4 -> #REF! | J11: =#REF!*COM!$J$4 -> #REF! | K11: =#REF!*COM!$J$4 -> #REF! | L11: =#REF!*COM!$L$4 -> #REF! | M11: =#REF!*COM!$L$4 -> #REF! | N11: =#REF!*COM!$N$4 -> #REF! | O11: =#REF!*COM!$N$4 -> #REF! | P11: =#REF!*COM!$P$4 -> #REF! | Q11: =#REF!*COM!$P$4 -> #REF! | R11: =#REF!*COM!$R$4 -> #REF! | S11: =#REF!*COM!$R$4 -> #REF! | T11: =I11+K11+M11+O11+Q11+S11 -> #REF!
A12: 311 | B12: 25 | C12: 920 | D12: 70499 | E12: ИФЦА | F12: Цепочка добавленной стоимости агрофинансирования-2 (ИФЦА) (грант) | H12: =#REF!*COM!$H$4 -> #REF! | I12: =#REF!*COM!$H$4 -> #REF! | J12: =#REF!*COM!$J$4 -> #REF! | K12: =#REF!*COM!$J$4 -> #REF! | L12: =#REF!*COM!$L$4 -> #REF! | M12: =#REF!*COM!$L$4 -> #REF! | N12: =#REF!*COM!$N$4 -> #REF! | O12: =#REF!*COM!$N$4 -> #REF! | P12: =#REF!*COM!$P$4 -> #REF! | Q12: =#REF!*COM!$P$4 -> #REF! | R12: =#REF!*COM!$R$4 -> #REF! | S12: =#REF!*COM!$R$4 -> #REF! | T12: =I12+K12+M12+O12+Q12+S12 -> #REF!
A13: 321 | B13: 25 | C13: 930 | D13: 70499 | E13: ЕИБ | F13: Цепочка добавленной стоимости агрофинансирования-2 (ЕИБ) (кредит) | G13: FI № 84.373 | H13: =#REF!*COM!$H$4 -> #REF! | I13: =#REF!*COM!$H$4 -> #REF! | J13: =#REF!*COM!$J$4 -> #REF! | K13: =#REF!*COM!$J$4 -> #REF! | L13: =#REF!*COM!$L$4 -> #REF! | M13: =#REF!*COM!$L$4 -> #REF! | N13: =#REF!*COM!$N$4 -> #REF! | O13: =#REF!*COM!$N$4 -> #REF! | P13: =#REF!*COM!$P$4 -> #REF! | Q13: =#REF!*COM!$P$4 -> #REF! | R13: =#REF!*COM!$R$4 -> #REF! | S13: =#REF!*COM!$R$4 -> #REF! | T13: =I13+K13+M13+O13+Q13+S13 -> #REF!
A14: 311 | B14: 25 | C14: 920 | D14: 70499 | E14: ВБ | F14: Комплексное повышение производительности молочного сектора (ВБ) (грант) Доп. Финансирование | H14: =#REF!*COM!$H$4 -> #REF! | I14: =#REF!*COM!$H$4 -> #REF! | J14: =#REF!*COM!$J$4 -> #REF! | K14: =#REF!*COM!$J$4 -> #REF! | L14: =#REF!*COM!$L$4 -> #REF! | M14: =#REF!*COM!$L$4 -> #REF! | N14: =#REF!*COM!$N$4 -> #REF! | O14: =#REF!*COM!$N$4 -> #REF! | P14: =#REF!*COM!$P$4 -> #REF! | Q14: =#REF!*COM!$P$4 -> #REF! | R14: =#REF!*COM!$R$4 -> #REF! | S14: =#REF!*COM!$R$4 -> #REF! | T14: =I14+K14+M14+O14+Q14+S14 -> #REF!
A15: 321 | B15: 25 | C15: 920 | D15: 70499 | E15: ВБ | F15: Комплексное повышение производительности молочного сектора (ВБ) (грант) Доп. Финансирование | H15: =#REF!*COM!$H$4 -> #REF! | I15: =#REF!*COM!$H$4 -> #REF! | J15: =#REF!*COM!$J$4 -> #REF! | K15: =#REF!*COM!$J$4 -> #REF! | L15: =#REF!*COM!$L$4 -> #REF! | M15: =#REF!*COM!$L$4 -> #REF! | N15: =#REF!*COM!$N$4 -> #REF! | O15: =#REF!*COM!$N$4 -> #REF! | P15: =#REF!*COM!$P$4 -> #REF! | Q15: =#REF!*COM!$P$4 -> #REF! | R15: =#REF!*COM!$R$4 -> #REF! | S15: =#REF!*COM!$R$4 -> #REF! | T15: =I15+K15+M15+O15+Q15+S15 -> #REF!
A16: 311 | B16: 25 | C16: 930 | D16: 70499 | E16: ВБ | F16: Комплексное повышение производительности молочного сектора (ВБ) (кредит) Доп. Финансирование | G16: № 6941-KG | H16: =#REF!*COM!$H$4 -> #REF! | I16: =#REF!*COM!$H$4 -> #REF! | J16: =#REF!*COM!$J$4 -> #REF! | K16: =#REF!*COM!$J$4 -> #REF! | L16: =#REF!*COM!$L$4 -> #REF! | M16: =#REF!*COM!$L$4 -> #REF! | N16: =#REF!*COM!$N$4 -> #REF! | O16: =#REF!*COM!$N$4 -> #REF! | P16: =#REF!*COM!$P$4 -> #REF! | Q16: =#REF!*COM!$P$4 -> #REF! | R16: =#REF!*COM!$R$4 -> #REF! | S16: =#REF!*COM!$R$4 -> #REF! | T16: =I16+K16+M16+O16+Q16+S16 -> #REF!
A17: 321 | B17: 25 | C17: 930 | D17: 70499 | E17: ВБ | F17: Комплексное повышение производительности молочного сектора (ВБ) (кредит) Доп. Финансирование | H17: =#REF!*COM!$H$4 -> #REF! | I17: =#REF!*COM!$H$4 -> #REF! | J17: =#REF!*COM!$J$4 -> #REF! | K17: =#REF!*COM!$J$4 -> #REF! | L17: =#REF!*COM!$L$4 -> #REF! | M17: =#REF!*COM!$L$4 -> #REF! | N17: =#REF!*COM!$N$4 -> #REF! | O17: =#REF!*COM!$N$4 -> #REF! | P17: =#REF!*COM!$P$4 -> #REF! | Q17: =#REF!*COM!$P$4 -> #REF! | R17: =#REF!*COM!$R$4 -> #REF! | S17: =#REF!*COM!$R$4 -> #REF! | T17: =I17+K17+M17+O17+Q17+S17 -> #REF!
A18: 311 | B18: 25 | C18: 920 | D18: 70499 | E18: ВБ | F18: Проект по поддержке частного сектора (ВБ) (грант) | H18: =#REF!*COM!$H$4 -> #REF! | I18: =#REF!*COM!$H$4 -> #REF! | J18: =#REF!*COM!$J$4 -> #REF! | K18: =#REF!*COM!$J$4 -> #REF! | L18: =#REF!*COM!$L$4 -> #REF! | M18: =#REF!*COM!$L$4 -> #REF! | N18: =#REF!*COM!$N$4 -> #REF! | O18: =#REF!*COM!$N$4 -> #REF! | P18: =#REF!*COM!$P$4 -> #REF! | Q18: =#REF!*COM!$P$4 -> #REF! | R18: =#REF!*COM!$R$4 -> #REF! | S18: =#REF!*COM!$R$4 -> #REF! | T18: =I18+K18+M18+O18+Q18+S18 -> #REF!
A19: 321 | B19: 25 | C19: 920 | D19: 70499 | E19: ВБ | F19: Проект по поддержке частного сектора (ВБ) (грант) | H19: =#REF!*COM!$H$4 -> #REF! | I19: =#REF!*COM!$H$4 -> #REF! | J19: =#REF!*COM!$J$4 -> #REF! | K19: =#REF!*COM!$J$4 -> #REF! | L19: =#REF!*COM!$L$4 -> #REF! | M19: =#REF!*COM!$L$4 -> #REF! | N19: =#REF!*COM!$N$4 -> #REF! | O19: =#REF!*COM!$N$4 -> #REF! | P19: =#REF!*COM!$P$4 -> #REF! | Q19: =#REF!*COM!$P$4 -> #REF! | R19: =#REF!*COM!$R$4 -> #REF! | S19: =#REF!*COM!$R$4 -> #REF! | T19: =I19+K19+M19+O19+Q19+S19 -> #REF!
A20: 321 | B20: 25 | C20: 930 | D20: 70499 | E20: ВБ | F20: Проект по поддержке частного сектора (ВБ) (кредит) | G20: № 6758-KG | H20: =#REF!*COM!$H$4 -> #REF! | I20: =#REF!*COM!$H$4 -> #REF! | J20: =#REF!*COM!$J$4 -> #REF! | K20: =#REF!*COM!$J$4 -> #REF! | L20: =#REF!*COM!$L$4 -> #REF! | M20: =#REF!*COM!$L$4 -> #REF! | N20: =#REF!*COM!$N$4 -> #REF! | O20: =#REF!*COM!$N$4 -> #REF! | P20: =#REF!*COM!$P$4 -> #REF! | Q20: =#REF!*COM!$P$4 -> #REF! | R20: =#REF!*COM!$R$4 -> #REF! | S20: =#REF!*COM!$R$4 -> #REF! | T20: =I20+K20+M20+O20+Q20+S20 -> #REF!
A21: 311 | B21: 25 | C21: 930 | D21: 70499 | E21: АБИИ | F21: Проект по поддержке частного сектора (АБИИ) (кредит) | G21: № 0423-А | H21: =#REF!*COM!$H$4 -> #REF! | I21: =#REF!*COM!$H$4 -> #REF! | J21: =#REF!*COM!$J$4 -> #REF! | K21: =#REF!*COM!$J$4 -> #REF! | L21: =#REF!*COM!$L$4 -> #REF! | M21: =#REF!*COM!$L$4 -> #REF! | N21: =#REF!*COM!$N$4 -> #REF! | O21: =#REF!*COM!$N$4 -> #REF! | P21: =#REF!*COM!$P$4 -> #REF! | Q21: =#REF!*COM!$P$4 -> #REF! | R21: =#REF!*COM!$R$4 -> #REF! | S21: =#REF!*COM!$R$4 -> #REF! | T21: =I21+K21+M21+O21+Q21+S21 -> #REF!
A22: 321 | B22: 25 | C22: 930 | D22: 70499 | E22: АБИИ | F22: Проект по поддержке частного сектора (АБИИ) (кредит) | H22: =#REF!*COM!$H$4 -> #REF! | I22: =#REF!*COM!$H$4 -> #REF! | J22: =#REF!*COM!$J$4 -> #REF! | K22: =#REF!*COM!$J$4 -> #REF! | L22: =#REF!*COM!$L$4 -> #REF! | M22: =#REF!*COM!$L$4 -> #REF! | N22: =#REF!*COM!$N$4 -> #REF! | O22: =#REF!*COM!$N$4 -> #REF! | P22: =#REF!*COM!$P$4 -> #REF! | Q22: =#REF!*COM!$P$4 -> #REF! | R22: =#REF!*COM!$R$4 -> #REF! | S22: =#REF!*COM!$R$4 -> #REF! | T22: =I22+K22+M22+O22+Q22+S22 -> #REF!
A23: 311 | B23: 25 | C23: 920 | D23: 70499 | E23: ВБ | F23: Экстренная поддержка микро, малых и средних предприятий ДФ (ВБ) (грант) | H23: =#REF!*COM!$H$4 -> #REF! | I23: =#REF!*COM!$H$4 -> #REF! | J23: =#REF!*COM!$J$4 -> #REF! | K23: =#REF!*COM!$J$4 -> #REF! | L23: =#REF!*COM!$L$4 -> #REF! | M23: =#REF!*COM!$L$4 -> #REF! | N23: =#REF!*COM!$N$4 -> #REF! | O23: =#REF!*COM!$N$4 -> #REF! | P23: =#REF!*COM!$P$4 -> #REF! | Q23: =#REF!*COM!$P$4 -> #REF! | R23: =#REF!*COM!$R$4 -> #REF! | S23: =#REF!*COM!$R$4 -> #REF! | T23: =I23+K23+M23+O23+Q23+S23 -> #REF!
A24: 321 | B24: 25 | C24: 920 | D24: 70499 | E24: ВБ | F24: Экстренная поддержка микро, малых и средних предприятий ДФ (ВБ) (грант) | H24: =#REF!*COM!$H$4 -> #REF! | I24: =#REF!*COM!$H$4 -> #REF! | J24: =#REF!*COM!$J$4 -> #REF! | K24: =#REF!*COM!$J$4 -> #REF! | L24: =#REF!*COM!$L$4 -> #REF! | M24: =#REF!*COM!$L$4 -> #REF! | N24: =#REF!*COM!$N$4 -> #REF! | O24: =#REF!*COM!$N$4 -> #REF! | P24: =#REF!*COM!$P$4 -> #REF! | Q24: =#REF!*COM!$P$4 -> #REF! | R24: =#REF!*COM!$R$4 -> #REF! | S24: =#REF!*COM!$R$4 -> #REF! | T24: =I24+K24+M24+O24+Q24+S24 -> #REF!
A25: 321 | B25: 25 | C25: 930 | D25: 70499 | E25: ВБ | F25: Экстренная поддержка микро, малых и средних предприятий ДФ (ВБ) (кредит) | G25: № 7094-KG | H25: =#REF!*COM!$H$4 -> #REF! | I25: =#REF!*COM!$H$4 -> #REF! | J25: =#REF!*COM!$J$4 -> #REF! | K25: =#REF!*COM!$J$4 -> #REF! | L25: =#REF!*COM!$L$4 -> #REF! | M25: =#REF!*COM!$L$4 -> #REF! | N25: =#REF!*COM!$N$4 -> #REF! | O25: =#REF!*COM!$N$4 -> #REF! | P25: =#REF!*COM!$P$4 -> #REF! | Q25: =#REF!*COM!$P$4 -> #REF! | R25: =#REF!*COM!$R$4 -> #REF! | S25: =#REF!*COM!$R$4 -> #REF! | T25: =I25+K25+M25+O25+Q25+S25 -> #REF!
A26: 311 | B26: 25 | C26: 930 | D26: 70499 | E26: ВБ | F26: Улучшение качества воздуха в городе Бишкек (ВБ) (кредит) | G26: № 7434-KG | H26: =#REF!*COM!$H$4 -> #REF! | I26: =#REF!*COM!$H$4 -> #REF! | J26: =#REF!*COM!$J$4 -> #REF! | K26: =#REF!*COM!$J$4 -> #REF! | L26: =#REF!*COM!$L$4 -> #REF! | M26: =#REF!*COM!$L$4 -> #REF! | N26: =#REF!*COM!$N$4 -> #REF! | O26: =#REF!*COM!$N$4 -> #REF! | P26: =#REF!*COM!$P$4 -> #REF! | Q26: =#REF!*COM!$P$4 -> #REF! | R26: =#REF!*COM!$R$4 -> #REF! | S26: =#REF!*COM!$R$4 -> #REF! | T26: =I26+K26+M26+O26+Q26+S26 -> #REF!
A27: 321 | B27: 25 | C27: 930 | D27: 70499 | E27: ВБ | F27: Улучшение качества воздуха в городе Бишкек (ВБ) (кредит) | H27: =#REF!*COM!$H$4 -> #REF! | I27: =#REF!*COM!$H$4 -> #REF! | J27: =#REF!*COM!$J$4 -> #REF! | K27: =#REF!*COM!$J$4 -> #REF! | L27: =#REF!*COM!$L$4 -> #REF! | M27: =#REF!*COM!$L$4 -> #REF! | N27: =#REF!*COM!$N$4 -> #REF! | O27: =#REF!*COM!$N$4 -> #REF! | P27: =#REF!*COM!$P$4 -> #REF! | Q27: =#REF!*COM!$P$4 -> #REF! | R27: =#REF!*COM!$R$4 -> #REF! | S27: =#REF!*COM!$R$4 -> #REF! | T27: =I27+K27+M27+O27+Q27+S27 -> #REF!
A28: 311 | B28: 25 | C28: 930 | D28: 70499 | E28: ВБ | F28: Проект развития устойчивых агропродовольственных кластеров (ВБ) (кредит) | G28: № 7526-KG | H28: =#REF!*COM!$H$4 -> #REF! | I28: =#REF!*COM!$H$4 -> #REF! | J28: =#REF!*COM!$J$4 -> #REF! | K28: =#REF!*COM!$J$4 -> #REF! | L28: =#REF!*COM!$L$4 -> #REF! | M28: =#REF!*COM!$L$4 -> #REF! | N28: =#REF!*COM!$N$4 -> #REF! | O28: =#REF!*COM!$N$4 -> #REF! | P28: =#REF!*COM!$P$4 -> #REF! | Q28: =#REF!*COM!$P$4 -> #REF! | R28: =#REF!*COM!$R$4 -> #REF! | S28: =#REF!*COM!$R$4 -> #REF! | T28: =I28+K28+M28+O28+Q28+S28 -> #REF!
A29: 321 | B29: 25 | C29: 930 | D29: 70499 | E29: ВБ | F29: Проект развития устойчивых агропродовольственных кластеров (ВБ) (кредит) | H29: =#REF!*COM!$H$4 -> #REF! | I29: =#REF!*COM!$H$4 -> #REF! | J29: =#REF!*COM!$J$4 -> #REF! | K29: =#REF!*COM!$J$4 -> #REF! | L29: =#REF!*COM!$L$4 -> #REF! | M29: =#REF!*COM!$L$4 -> #REF! | N29: =#REF!*COM!$N$4 -> #REF! | O29: =#REF!*COM!$N$4 -> #REF! | P29: =#REF!*COM!$P$4 -> #REF! | Q29: =#REF!*COM!$P$4 -> #REF! | R29: =#REF!*COM!$R$4 -> #REF! | S29: =#REF!*COM!$R$4 -> #REF! | T29: =I29+K29+M29+O29+Q29+S29 -> #REF!
A30: 311 | B30: 25 | C30: 930 | D30: 70499 | E30: ВБ | F30: Развитие устойчивых финансовых рынков для микро-, малых и средних предприятий в Кыргызской Республике (ВБ) (кредит) (план) | G30: 7741-KG | H30: =#REF!*COM!$H$4 -> #REF! | I30: =#REF!*COM!$H$4 -> #REF! | J30: =#REF!*COM!$J$4 -> #REF! | K30: =#REF!*COM!$J$4 -> #REF! | L30: =#REF!*COM!$L$4 -> #REF! | M30: =#REF!*COM!$L$4 -> #REF! | N30: =#REF!*COM!$N$4 -> #REF! | O30: =#REF!*COM!$N$4 -> #REF! | P30: =#REF!*COM!$P$4 -> #REF! | Q30: =#REF!*COM!$P$4 -> #REF! | R30: =#REF!*COM!$R$4 -> #REF! | S30: =#REF!*COM!$R$4 -> #REF! | T30: =I30+K30+M30+O30+Q30+S30 -> #REF!
A31: 321 | B31: 25 | C31: 930 | D31: 70499 | E31: ВБ | F31: Развитие устойчивых финансовых рынков для микро-, малых и средних предприятий в Кыргызской Республике (ВБ) (кредит) (план) | H31: =#REF!*COM!$H$4 -> #REF! | I31: =#REF!*COM!$H$4 -> #REF! | J31: =#REF!*COM!$J$4 -> #REF! | K31: =#REF!*COM!$J$4 -> #REF! | L31: =#REF!*COM!$L$4 -> #REF! | M31: =#REF!*COM!$L$4 -> #REF! | N31: =#REF!*COM!$N$4 -> #REF! | O31: =#REF!*COM!$N$4 -> #REF! | P31: =#REF!*COM!$P$4 -> #REF! | Q31: =#REF!*COM!$P$4 -> #REF! | R31: =#REF!*COM!$R$4 -> #REF! | S31: =#REF!*COM!$R$4 -> #REF! | T31: =I31+K31+M31+O31+Q31+S31 -> #REF!
A32: 311 | B32: 25 | C32: 920 | D32: 70499 | E32: ВБ | F32: Проект сельских инвестиций - 3 ДФ (ВБ) (грант) | H32: =#REF!*COM!$H$4 -> #REF! | I32: =#REF!*COM!$H$4 -> #REF! | J32: =#REF!*COM!$J$4 -> #REF! | K32: =#REF!*COM!$J$4 -> #REF! | L32: =#REF!*COM!$L$4 -> #REF! | M32: =#REF!*COM!$L$4 -> #REF! | N32: =#REF!*COM!$N$4 -> #REF! | O32: =#REF!*COM!$N$4 -> #REF! | P32: =#REF!*COM!$P$4 -> #REF! | Q32: =#REF!*COM!$P$4 -> #REF! | R32: =#REF!*COM!$R$4 -> #REF! | S32: =#REF!*COM!$R$4 -> #REF!
A33: 311 | B33: 25 | C33: 930 | D33: 70499 | E33: ВБ | F33: Проект сельских инвестиций - 3 ДФ (ВБ) (кредит) | H33: =#REF!*COM!$H$4 -> #REF! | I33: =#REF!*COM!$H$4 -> #REF! | J33: =#REF!*COM!$J$4 -> #REF! | K33: =#REF!*COM!$J$4 -> #REF! | L33: =#REF!*COM!$L$4 -> #REF! | M33: =#REF!*COM!$L$4 -> #REF! | N33: =#REF!*COM!$N$4 -> #REF! | O33: =#REF!*COM!$N$4 -> #REF! | P33: =#REF!*COM!$P$4 -> #REF! | Q33: =#REF!*COM!$P$4 -> #REF! | R33: =#REF!*COM!$R$4 -> #REF! | S33: =#REF!*COM!$R$4 -> #REF!
T34: =I34+K34+M34+O34+Q34+S34 -> 0
T36: =I36+K36+M36+O36+Q36+S36 -> 0
T37: =I37+K37+M37+O37+Q37+S37 -> 0
T38: =I38+K38+M38+O38+Q38+S38 -> 0
F39: Министерство экономики и коммерции КР | H39: =H40 -> #REF! | I39: =I40 -> #REF! | J39: =J40 -> #REF! | K39: =K40 -> #REF! | L39: =L40 -> #REF! | M39: =M40 -> #REF! | N39: =N40 -> #REF! | O39: =O40 -> #REF! | ... S39: =S40 -> #REF! | T39: =I39+K39+M39+O39+Q39+S39 -> #REF!
F40: Государственные инвестиции | H40: =SUM(H41:H68) -> #REF! | I40: =SUM(I41:I68) -> #REF! | J40: =SUM(J41:J68) -> #REF! | K40: =SUM(K41:K68) -> #REF! | L40: =SUM(L41:L68) -> #REF! | M40: =SUM(M41:M68) -> #REF! | N40: =SUM(N41:N68) -> #REF! | O40: =SUM(O41:O68) -> #REF! | ... S40: =SUM(S41:S68) -> #REF! | T40: =I40+K40+M40+O40+Q40+S40 -> #REF!
A41: 311 | B41: 28 | C41: 920 | D41: 70499 | E41: ВБ | F41: Проект регионального экономического развития Ошской области (ВБ) (грант) | G41: Грант D5700-KG/Кредит 6558-KG | H41: =#REF!*COM!$H$4 -> #REF! | I41: =#REF!*COM!$H$4 -> #REF! | J41: =#REF!*COM!$J$4 -> #REF! | K41: =#REF!*COM!$J$4 -> #REF! | L41: =#REF!*COM!$L$4 -> #REF! | M41: =#REF!*COM!$L$4 -> #REF! | N41: =#REF!*COM!$N$4 -> #REF! | O41: =#REF!*COM!$N$4 -> #REF! | P41: =#REF!*COM!$P$4 -> #REF! | Q41: =#REF!*COM!$P$4 -> #REF! | R41: =#REF!*COM!$R$4 -> #REF! | S41: =#REF!*COM!$R$4 -> #REF! | T41: =I41+K41+M41+O41+Q41+S41 -> #REF!
A42: 311 | B42: 28 | C42: 930 | D42: 70499 | E42: ВБ | F42: Проект регионального экономического развития Ошской области (ВБ) (кредит) | H42: =#REF!*COM!$H$4 -> #REF! | I42: =#REF!*COM!$H$4 -> #REF! | J42: =#REF!*COM!$J$4 -> #REF! | K42: =#REF!*COM!$J$4 -> #REF! | L42: =#REF!*COM!$L$4 -> #REF! | M42: =#REF!*COM!$L$4 -> #REF! | N42: =#REF!*COM!$N$4 -> #REF! | O42: =#REF!*COM!$N$4 -> #REF! | P42: =#REF!*COM!$P$4 -> #REF! | Q42: =#REF!*COM!$P$4 -> #REF! | R42: =#REF!*COM!$R$4 -> #REF! | S42: =#REF!*COM!$R$4 -> #REF! | T42: =I42+K42+M42+O42+Q42+S42 -> #REF!
A43: 311 | B43: 28 | C43: 930 | D43: 70499 | E43: ВБ | F43: Проект регионального экономического развития Ошской области - дополнительное финансирование (ВБ) (кредит) | H43: =#REF!*COM!$H$4 -> #REF! | I43: =#REF!*COM!$H$4 -> #REF! | J43: =#REF!*COM!$J$4 -> #REF! | K43: =#REF!*COM!$J$4 -> #REF! | L43: =#REF!*COM!$L$4 -> #REF! | M43: =#REF!*COM!$L$4 -> #REF! | N43: =#REF!*COM!$N$4 -> #REF! | O43: =#REF!*COM!$N$4 -> #REF! | P43: =#REF!*COM!$P$4 -> #REF! | Q43: =#REF!*COM!$P$4 -> #REF! | R43: =#REF!*COM!$R$4 -> #REF! | S43: =#REF!*COM!$R$4 -> #REF! | T43: =I43+K43+M43+O43+Q43+S43 -> #REF!
A44: 311 | B44: 28 | C44: 920 | D44: 70499 | E44: ВБ | F44: Проект регионального экономического развития Баткенской области (ВБ) (грант) | G44: Грант D976-KG/Кредит 70490-KG | H44: =#REF!*COM!$H$4 -> #REF! | I44: =#REF!*COM!$H$4 -> #REF! | J44: =#REF!*COM!$J$4 -> #REF! | K44: =#REF!*COM!$J$4 -> #REF! | L44: =#REF!*COM!$L$4 -> #REF! | M44: =#REF!*COM!$L$4 -> #REF! | N44: =#REF!*COM!$N$4 -> #REF! | O44: =#REF!*COM!$N$4 -> #REF! | P44: =#REF!*COM!$P$4 -> #REF! | Q44: =#REF!*COM!$P$4 -> #REF! | R44: =#REF!*COM!$R$4 -> #REF! | S44: =#REF!*COM!$R$4 -> #REF! | T44: =I44+K44+M44+O44+Q44+S44 -> #REF!
...

Sheet СОМ (без формул)
H4: 91.6 | J4: 88.4 | L4: 89.3 | N4: 89.5 | P4: 90 | R4: 90.5
A5: Классификация | E5: донор | F5: Наименование проекта | G5: номер и дата кредитного соглашения | H5: 2025 | J5: 2026 | L5: 2027 | N5: 2028 | P5: 2029 | R5: 2030
A6: III | B6: IV | D6: V | H6: Внутреннее | I6: Внешнее | J6: Внутреннее | K6: Внешнее | L6: Внутреннее | M6: Внешнее | N6: Внутреннее | O6: Внешнее | P6: Внутреннее | Q6: Внешнее | R6: Внутреннее | S6: Внешнее
F7: Министерство финансов КР | H7: 0 | I7: 1106656.2 | J7: 243.1 | K7: 2252456.8 | L7: 3238.911 | M7: 2318887.9 | N7: 0 | O7: 1249038.7 | P7: 0 | Q7: 1453217.4 | R7: 0 | S7: 1039845 | T7: 9420102
F8: Государственные инвестиции | H8: 0 | I8: 1106656.2 | J8: 243.1 | K8: 2252456.8 | L8: 3238.911 | M8: 2318887.9 | N8: 0 | O8: 1249038.7 | P8: 0 | Q8: 1453217.4 | R8: 0 | S8: 1039845 | T8: 9420102
A9: 311 | B9: 25 | C9: 910 | D9: 70499 | F9: Цепочка добавленной стоимости агрофинансирования (КфВ) Фаза 2 | H9: 0 | I9: 0 | J9: 243.1 | K9: 0 | L9: 245.6 | M9: 0 | N9: 0 | O9: 0 | P9: 0 | Q9: 0 | R9: 0 | S9: 0 | T9: 0
A10: 311 | B10: 25 | C10: 920 | D10: 70499 | E10: КфВ | F10: Цепочка добавленной стоимости агрофинансирования (КфВ) (грант) Фаза 2 | H10: 0 | I10: 0 | J10: 0 | K10: 551000.7 | L10: 0 | M10: 425650.2 | N10: 0 | O10: 0 | P10: 0 | Q10: 0 | R10: 0 | S10: 0 | T10: 976650.97
A11: 311 | B11: 25 | C11: 910 | D11: 70499 | F11: Цепочка добавленной стоимости агрофинансирования-2 (ИФЦА) | H11: 0 | I11: 0 | J11: 0 | K11: 0 | L11: 2993.3 | M11: 0 | N11: 0 | O11: 0 | P11: 0 | Q11: 0 | R11: 0 | S11: 0 | T11: 0
A12: 311 | B12: 25 | C12: 920 | D12: 70499 | E12: ИФЦА | F12: Цепочка добавленной стоимости агрофинансирования-2 (ИФЦА) (грант) | H12: 0 | I12: 0 | J12: 0 | K12: 63875.2 | L12: 0 | M12: 227281 | N12: 0 | O12: 0 | P12: 0 | Q12: 0 | R12: 0 | S12: 0 | T12: 291156.19
A13: 321 | B13: 25 | C13: 930 | D13: 70499 | E13: ЕИБ | F13: Цепочка добавленной стоимости агрофинансирования-2 (ЕИБ) (кредит) | G13: FI № 84.373 | H13: 0 | I13: 0 | J13: 0 | K13: 486200 | L13: 0 | M13: 598310 | N13: 0 | O13: 179000 | P13: 0 | Q13: 450000 | R13: 0 | S13: 452500 | T13: 2166010
A14: 311 | B14: 25 | C14: 920 | D14: 70499 | E14: ВБ | F14: Комплексное повышение производительности молочного сектора (ВБ) (грант) Доп. Финансирование | H14: 0 | I14: 4251.2 | J14: 0 | K14: 0 | L14: 0 | M14: 0 | N14: 0 | O14: 0 | P14: 0 | Q14: 0 | R14: 0 | S14: 0 | T14: 4251.156
A15: 321 | B15: 25 | C15: 920 | D15: 70499 | E15: ВБ | F15: Комплексное повышение производительности молочного сектора (ВБ) (грант) Доп. Финансирование | H15: 0 | I15: 0 | J15: 0 | K15: 0 | L15: 0 | M15: 0 | N15: 0 | O15: 0 | P15: 0 | Q15: 0 | R15: 0 | S15: 0 | T15: 0
A16: 311 | B16: 25 | C16: 930 | D16: 70499 | E16: ВБ | F16: Комплексное повышение производительности молочного сектора (ВБ) (кредит) Доп. Финансирование | G16: № 6941-KG | H16: 0 | I16: 16179.3 | J16: 0 | K16: 0 | L16: 0 | M16: 0 | N16: 0 | O16: 0 | P16: 0 | Q16: 0 | R16: 0 | S16: 0 | T16: 16179.308
A17: 321 | B17: 25 | C17: 930 | D17: 70499 | E17: ВБ | F17: Комплексное повышение производительности молочного сектора (ВБ) (кредит) Доп. Финансирование | H17: 0 | I17: 333292.1 | J17: 0 | K17: 103251.2 | L17: 0 | M17: 0 | N17: 0 | O17: 0 | P17: 0 | Q17: 0 | R17: 0 | S17: 0 | T17: 436543.3
A18: 311 | B18: 25 | C18: 920 | D18: 70499 | E18: ВБ | F18: Проект по поддержке частного сектора (ВБ) (грант) | H18: 0 | I18: 0 | J18: 0 | K18: 0 | L18: 0 | M18: 0 | N18: 0 | O18: 0 | P18: 0 | Q18: 0 | R18: 0 | S18: 0 | T18: 0
A19: 321 | B19: 25 | C19: 920 | D19: 70499 | E19: ВБ | F19: Проект по поддержке частного сектора (ВБ) (грант) | H19: 0 | I19: 0 | J19: 0 | K19: 0 | L19: 0 | M19: 0 | N19: 0 | O19: 0 | P19: 0 | Q19: 0 | R19: 0 | S19: 0 | T19: 0
A20: 321 | B20: 25 | C20: 930 | D20: 70499 | E20: ВБ | F20: Проект по поддержке частного сектора (ВБ) (кредит) | G20: № 6758-KG | H20: 0 | I20: 0 | J20: 0 | K20: 0 | L20: 0 | M20: 0 | N20: 0 | O20: 0 | P20: 0 | Q20: 0 | R20: 0 | S20: 0 | T20: 0
A21: 311 | B21: 25 | C21: 930 | D21: 70499 | E21: АБИИ | F21: Проект по поддержке частного сектора (АБИИ) (кредит) | G21: № 0423-А | H21: 0 | I21: 2851.5 | J21: 0 | K21: 0 | L21: 0 | M21: 0 | N21: 0 | O21: 0 | P21: 0 | Q21: 0 | R21: 0 | S21: 0 | T21: 2851.508
A22: 321 | B22: 25 | C22: 930 | D22: 70499 | E22: АБИИ | F22: Проект по поддержке частного сектора (АБИИ) (кредит) | H22: 0 | I22: 731762.2 | J22: 0 | K22: 0 | L22: 0 | M22: 0 | N22: 0 | O22: 0 | P22: 0 | Q22: 0 | R22: 0 | S22: 0 | T22: 731762.17
A23: 311 | B23: 25 | C23: 920 | D23: 70499 | E23: ВБ | F23: Экстренная поддержка микро, малых и средних предприятий ДФ (ВБ) (грант) | H23: 0 | I23: 0 | J23: 0 | K23: 0 | L23: 0 | M23: 0 | N23: 0 | O23: 0 | P23: 0 | Q23: 0 | R23: 0 | S23: 0 | T23: 0
A24: 321 | B24: 25 | C24: 920 | D24: 70499 | E24: ВБ | F24: Экстренная поддержка микро, малых и средних предприятий ДФ (ВБ) (грант) | H24: 0 | I24: 0 | J24: 0 | K24: 0 | L24: 0 | M24: 0 | N24: 0 | O24: 0 | P24: 0 | Q24: 0 | R24: 0 | S24: 0 | T24: 0
A25: 321 | B25: 25 | C25: 930 | D25: 70499 | E25: ВБ | F25: Экстренная поддержка микро, малых и средних предприятий ДФ (ВБ) (кредит) | G25: № 7094-KG | H25: 0 | I25: 0 | J25: 0 | K25: 0 | L25: 0 | M25: 0 | N25: 0 | O25: 0 | P25: 0 | Q25: 0 | R25: 0 | S25: 0 | T25: 0
A26: 311 | B26: 25 | C26: 930 | D26: 70499 | E26: ВБ | F26: Улучшение качества воздуха в городе Бишкек (ВБ) (кредит) | G26: № 7434-KG | H26: 0 | I26: 0 | J26: 0 | K26: 4420 | L26: 0 | M26: 13395 | N26: 0 | O26: 13425 | P26: 0 | Q26: 13500 | R26: 0 | S26: 13575 | T26: 58315
A27: 321 | B27: 25 | C27: 930 | D27: 70499 | E27: ВБ | F27: Улучшение качества воздуха в городе Бишкек (ВБ) (кредит) | H27: 0 | I27: 0 | J27: 0 | K27: 542776 | L27: 0 | M27: 548302 | N27: 0 | O27: 549530 | P27: 0 | Q27: 552600 | R27: 0 | S27: 573770 | T27: 2766978
A28: 311 | B28: 25 | C28: 930 | D28: 70499 | E28: ВБ | F28: Проект развития устойчивых агропродовольственных кластеров (ВБ) (кредит) | G28: № 7526-KG | H28: 0 | I28: 0 | J28: 0 | K28: 12965.6 | L28: 0 | M28: 13013.7 | N28: 0 | O28: 13043.7 | P28: 0 | Q28: 19517.4 | R28: 0 | S28: 0 | T28: 58540.447
A29: 321 | B29: 25 | C29: 930 | D29: 70499 | E29: ВБ | F29: Проект развития устойчивых агропродовольственных кластеров (ВБ) (кредит) | H29: 0 | I29: 0 | J29: 0 | K29: 487968 | L29: 0 | M29: 492936 | N29: 0 | O29: 494040 | P29: 0 | Q29: 417600 | R29: 0 | S29: 0 | T29: 1892544
A30: 311 | B30: 25 | C30: 930 | D30: 70499 | E30: ВБ | F30: Развитие устойчивых финансовых рынков для микро-, малых и средних предприятий в Кыргызской Республике (ВБ) (кредит) (план) | G30: 7741-KG | H30: 0 | I30: 0 | J30: 0 | K30: 0 | L30: 0 | M30: 0 | N30: 0 | O30: 0 | P30: 0 | Q30: 0 | R30: 0 | S30: 0 | T30: 0
A31: 321 | B31: 25 | C31: 930 | D31: 70499 | E31: ВБ | F31: Развитие устойчивых финансовых рынков для микро-, малых и средних предприятий в Кыргызской Республике (ВБ) (кредит) (план) | H31: 0 | I31: 0 | J31: 0 | K31: 0 | L31: 0 | M31: 0 | N31: 0 | O31: 0 | P31: 0 | Q31: 0 | R31: 0 | S31: 0 | T31: 0
A32: 311 | B32: 25 | C32: 920 | D32: 70499 | E32: ВБ | F32: Проект сельских инвестиций - 3 ДФ (ВБ) (грант) | H32: 0 | I32: 0 | J32: 0 | K32: 0 | L32: 0 | M32: 0 | N32: 0 | O32: 0 | P32: 0 | Q32: 0 | R32: 0 | S32: 0
A33: 311 | B33: 25 | C33: 930 | D33: 70499 | E33: ВБ | F33: Проект сельских инвестиций - 3 ДФ (ВБ) (кредит) | H33: 0 | I33: 18320 | J33: 0 | K33: 0 | L33: 0 | M33: 0 | N33: 0 | O33: 0 | P33: 0 | Q33: 0 | R33: 0 | S33: 0
T34: 0
T36: 0
T37: 0
T38: 0
F39: Министерство экономики и коммерции КР | H39: 0 | I39: 5596760 | J39: 0 | K39: 4345551.3 | L39: 0 | M39: 3799801.6 | N39: 0 | O39: 7481928.8 | P39: 0 | Q39: 2764350 | R39: 0 | S39: 1577867.5 | T39: 25566259
F40: Государственные инвестиции | H40: 0 | I40: 5596760 | J40: 0 | K40: 4345551.3 | L40: 0 | M40: 3799801.6 | N40: 0 | O40: 7481928.8 | P40: 0 | Q40: 2764350 | R40: 0 | S40: 1577867.5 | T40: 25566259
A41: 311 | B41: 28 | C41: 920 | D41: 70499 | E41: ВБ | F41: Проект регионального экономического развития Ошской области (ВБ) (грант) | G41: Грант D5700-KG/Кредит 6558-KG | H41: 0 | I41: 916000 | J41: 0 | K41: 0 | L41: 0 | M41: 23276.045 | N41: 0 | O41: 0 | P41: 0 | Q41: 0 | R41: 0 | S41: 0 | T41: 939276.05
A42: 311 | B42: 28 | C42: 930 | D42: 70499 | E42: ВБ | F42: Проект регионального экономического развития Ошской области (ВБ) (кредит) | H42: 0 | I42: 732800 | J42: 0 | K42: 1591200 | L42: 0 | M42: 357200 | N42: 0 | O42: 0 | P42: 0 | Q42: 0 | R42: 0 | S42: 0 | T42: 2681200
A43: 311 | B43: 28 | C43: 930 | D43: 70499 | E43: ВБ | F43: Проект регионального экономического развития Ошской области - дополнительное финансирование (ВБ) (кредит) | H43: 0 | I43: 0 | J43: 0 | K43: 88400 | L43: 0 | M43: 267900 | N43: 0 | O43: 358000 | P43: 0 | Q43: 45000 | R43: 0 | S43: 0 | T43: 759300
A44: 311 | B44: 28 | C44: 920 | D44: 70499 | E44: ВБ | F44: Проект регионального экономического развития Баткенской области (ВБ) (грант) | G44: Грант D976-KG/Кредит 70490-KG | H44: 0 | I44: 732800 | J44: 0 | K44: 751400 | L44: 0 | M44: 491150 | N44: 0 | O44: 25346.4 | P44: 0 | Q44: 0 | R44: 0 | S44: 0 | T44: 2000696.4
...

Sheet Приложение 8
H1: Приложение 8 к Закону Кыргызской Республики «О республиканском бюджете Кыргызской Республики на 2026 год и плановый период 2027–2028 годов»
A3: Бюджет государственных инвестиций на 2026–2028 годы
F4: 88.4 | H4: 89.3 | J4: 89.5 | K4: (тыс. сом.)
A5: Классификация | E5: Наименование проекта | F5: 2026 год (проект) | H5: 2027 год (плановый период) | J5: 2028 год (плановый период)
A6: III | B6: IV | D6: V | F6: Внутреннее | G6: Внешнее | H6: Внутреннее | I6: Внешнее | J6: Внутреннее | K6: Внешнее
E7: Министерство финансов Кыргызской Республики | F7: 243.1 | G7: 2252456.7 | H7: 3238.9 | I7: 2318887.9 | J7: 0 | K7: 1249038.7
E8: Государственные инвестиции | F8: 243.1 | G8: 2252456.7 | H8: 3238.9 | I8: 2318887.9 | J8: 0 | K8: 1249038.7
A9: 311 | B9: 25 | C9: 910 | D9: 70499 | E9: Цепочка добавленной стоимости агрофинансирования (КфВ) Фаза 2 | F9: 243.1 | G9: 0 | H9: 245.6 | I9: 0 | J9: 0 | K9: 0
A10: 311 | B10: 25 | C10: 920 | D10: 70499 | E10: Цепочка добавленной стоимости агрофинансирования (КфВ) (грант) Фаза 2 | F10: 0 | G10: 551000.7 | H10: 0 | I10: 425650.2 | J10: 0 | K10: 0
A11: 311 | B11: 25 | C11: 910 | D11: 70499 | E11: Цепочка добавленной стоимости агрофинансирования-2 (ИФЦА) | F11: 0 | G11: 0 | H11: 2993.3 | I11: 0 | J11: 0 | K11: 0
A12: 311 | B12: 25 | C12: 920 | D12: 70499 | E12: Цепочка добавленной стоимости агрофинансирования-2 (ИФЦА) (грант) | F12: 0 | G12: 63875.2 | H12: 0 | I12: 227281 | J12: 0 | K12: 0
A13: 321 | B13: 25 | C13: 930 | D13: 70499 | E13: Цепочка добавленной стоимости агрофинансирования-2 (ЕИБ) (кредит) | F13: 0 | G13: 486200 | H13: 0 | I13: 598310 | J13: 0 | K13: 179000
A14: 311 | B14: 25 | C14: 920 | D14: 70499 | E14: Комплексное повышение производительности молочного сектора (ВБ) (грант) Доп. Финансирование | F14: 0 | G14: 0 | H14: 0 | I14: 0 | J14: 0 | K14: 0
A15: 321 | B15: 25 | C15: 920 | D15: 70499 | E15: Комплексное повышение производительности молочного сектора (ВБ) (грант) Доп. Финансирование | F15: 0 | G15: 0 | H15: 0 | I15: 0 | J15: 0 | K15: 0
A16: 311 | B16: 25 | C16: 930 | D16: 70499 | E16: Комплексное повышение производительности молочного сектора (ВБ) (кредит) Доп. Финансирование | F16: 0 | G16: 0 | H16: 0 | I16: 0 | J16: 0 | K16: 0
A17: 321 | B17: 25 | C17: 930 | D17: 70499 | E17: Комплексное повышение производительности молочного сектора (ВБ) (кредит) Доп. Финансирование | F17: 0 | G17: 103251.2 | H17: 0 | I17: 0 | J17: 0 | K17: 0
A18: 311 | B18: 25 | C18: 920 | D18: 70499 | E18: Проект по поддержке частного сектора (ВБ) (грант) | F18: 0 | G18: 0 | H18: 0 | I18: 0 | J18: 0 | K18: 0
A19: 321 | B19: 25 | C19: 920 | D19: 70499 | E19: Проект по поддержке частного сектора (ВБ) (грант) | F19: 0 | G19: 0 | H19: 0 | I19: 0 | J19: 0 | K19: 0
A20: 321 | B20: 25 | C20: 930 | D20: 70499 | E20: Проект по поддержке частного сектора (ВБ) (кредит) | F20: 0 | G20: 0 | H20: 0 | I20: 0 | J20: 0 | K20: 0
... A31: 321 | B31: 25 | C31: 930 | D31: 70499 | E31: Развитие устойчивых финансовых рынков для микро-, малых и средних предприятий в Кыргызской Республике (ВБ) (кредит) (план) | F31: 0 | G31: 0 | H31: 0 | I31: 0 | J31: 0 | K31: 0
A32: 311 | B32: 25 | C32: 930 | D32: 70499 | E32: Развитие устойчивых финансовых рынков для микро-, малых и средних предприятий в Кыргызской Республике (АБИИ) (кредит) (план)
A33: 321 | B33: 25 | C33: 930 | D33: 70499 | E33: Развитие устойчивых финансовых рынков для микро-, малых и средних предприятий в Кыргызской Республике (АБИИ) (кредит) (план)
E35: Министерство экономики и коммерции Кыргызской Республики | F35: 0 | G35: 4345551.3 | H35: 0 | I35: 3799801.6 | J35: 0 | K35: 7481928.9
E36: Государственные инвестиции | F36: 0 | G36: 4345551.3 | H36: 0 | I36: 3799801.6 | J36: 0 | K36: 7481928.9
A37: 311 | B37: 28 | C37: 920 | D37: 70499 | E37: Проект регионального экономического развития Ошской области (ВБ) (грант) | F37: 0 | G37: 0 | H37: 0 | I37: 23276 | J37: 0 | K37: 0
A38: 311 | B38: 28 | C38: 930 | D38: 70499 | E38: Проект регионального экономического развития Ошской области (ВБ) (кредит) | F38: 0 | G38: 1591200 | H38: 0 | I38: 357200 | J38: 0 | K38: 0
A39: 311 | B39: 28 | C39: 930 | D39: 70499 | E39: Проект регионального экономического развития Ошской области - дополнительное финансирование (ВБ) (кредит) | F39: 0 | G39: 88400 | H39: 0 | I39: 267900 | J39: 0 | K39: 358000
A40: 311 | B40: 28 | C40: 920 | D40: 70499 | E40: Проект регионального экономического развития Баткенской области (ВБ) (грант) | F40: 0 | G40: 751400 | H40: 0 | I40: 491150 | J40: 0 | K40: 25346.4
A41: 311 | B41: 28 | C41: 930 | D41: 70499 | E41: Проект регионального экономического развития Баткенской области (ВБ) (кредит) | F41: 0 | G41: 353600 | H41: 0 | I41: 357200 | J41: 0 | K41: 156038.8
A42: 311 | B42: 28 | C42: 920 | D42: 70499 | E42: Национальный проект по инициативе сообществ (ВБ) (грант) | F42: 0 | G42: 17680 | H42: 0 | I42: 142880 | J42: 0 | K42: 0
A43: 311 | B43: 28 | C43: 930 | D43: 70499 | E43: Национальный проект по инициативе сообществ (ВБ) (кредит) | F43: 0 | G43: 159120 | H43: 0 | I43: 446500 | J43: 0 | K43: 1074000
A44: 311 | B44: 28 | C44: 910 | D44: 70499 | E44: Деятельность «Развитие центра бизнес-услуг», SEFF 2 (АБР) (план) | F44: 0 | G44: 0 | H44: 0 | I44: 0 | J44: 0 | K44: 0
A45: 311 | B45: 28 | C45: 920 | D45: 70499 | E45: Деятельность «Развитие центра бизнес-услуг», SEFF 2 (АБР) (грант) (план) | F45: 0 | G45: 0 | H45: 0 | I45: 0 | J45: 0 | K45: 0
A46: 311 | B46: 28 | C46: 910 | D46: 70499 | E46: Программа зеленой трансформации общественных зданий (АБР) (план)
A47: 311 | B47: 28 | C47: 920 | D47: 70499 | E47: Программа зеленой трансформации общественных зданий (АБР) (грант) (план)
A48: 311 | B48: 28 | C48: 930 | D48: 70499 | E48: Программа зеленой трансформации общественных зданий (АБР) (кредит) (план)
A49: 311 | B49: 28 | C49: 920 | D49: 70499 | E49: Программа жилищного финансирования (КфВ) (грант) | F49: 0 | G49: 2073.9 | H49: 0 | I49: 0 | J49: 0 | K49: 0
A50: 311 | B50: 28 | C50: 920 | D50: 70499 | E50: Программа жилищного финансирования (КфВ) (грант) Фаза 2 (план) | F50: 0 | G50: 11877.4 | H50: 0 | I50: 14093.3 | J50: 0 | K50: 14124.9
A51: 311 | B51: 28 | C51: 910 | D51: 70499 | E51: Строительство многоэтажных социальных жилых домов (СФР) | F51: 0 | G51: 0 | H51: 0 | I51: 0 | J51: 0 | K51: 0
A52: 321 | B52: 28 | C52: 930 | D52: 70499 | E52: Строительство многоэтажных социальных жилых домов (СФР) (кредит) | F52: 0 | G52: 1326000 | H52: 0 | I52: 1339500 | J52: 0 | K52: 2808510
...

Sheet СОМ(без формул до десятых) 24
L4: 91.6 | N4: 88.4 | P4: 89.3 | R4: 89.5 | T4: 90 | V4: 90.5
A5: Классификация | E5: донор | F5: Наименование проекта | G5: номер и дата кредитного соглашения | H5: 2024 | L5: 2025 | N5: 2026 | P5: 2027 | R5: 2028 | T5: 2029 | V5: 2030
A6: III | B6: IV | D6: V | H6: Факт внутренний | I6: % к утвержденному | J6: Факт внешний | K6: % к утвержденному | L6: Внутреннее | M6: Внешнее | N6: Внутреннее | O6: Внешнее | P6: Внутреннее | Q6: Внешнее | R6: Внутреннее | S6: Внешнее | T6: Внутреннее | U6: Внешнее | V6: Внутреннее | W6: Внешнее
F7: Министерство финансов КР | L7: =L8 -> #REF! | M7: =M8 -> #REF! | N7: =N8 -> #REF! | O7: =O8 -> #REF! | P7: =P8 -> #REF! | Q7: =Q8 -> #REF! | R7: =R8 -> #REF! | S7: =S8 -> #REF! | ... W7: =W8 -> #REF! | X7: =M7+O7+Q7+S7+U7+W7 -> #REF!
F8: Государственные инвестиции | L8: =SUM(L9:L38) -> #REF! | M8: =SUM(M9:M38) -> #REF! | N8: =SUM(N9:N38) -> #REF! | O8: =SUM(O9:O38) -> #REF! | P8: =SUM(P9:P38) -> #REF! | Q8: =SUM(Q9:Q38) -> #REF! | R8: =SUM(R9:R38) -> #REF! | S8: =SUM(S9:S38) -> #REF! | ... W8: =SUM(W9:W38) -> #REF! | X8: =M8+O8+Q8+S8+U8+W8 -> #REF!
A9: 311 | B9: 25 | C9: 910 | D9: 70499 | F9: Цепочка добавленной стоимости агрофинансирования (КфВ) Фаза 2 | L9: =ROUND(COM!H9,1) -> #REF! | M9: =ROUND(COM!I9,1) -> #REF! | N9: =ROUND(COM!J9,1) -> #REF! | O9: =ROUND(COM!K9,1) -> #REF! | P9: =ROUND(COM!L9,1) -> #REF! | Q9: =ROUND(COM!M9,1) -> #REF! | R9: =ROUND(COM!N9,1) -> #REF! | S9: =ROUND(COM!O9,1) -> #REF! | ... W9: =ROUND(COM!S9,1) -> #REF! | X9: =M9+O9+Q9+S9+U9+W9 -> #REF!
A10: 311 | B10: 25 | C10: 920 | D10: 70499 | E10: КфВ | F10: Цепочка добавленной стоимости агрофинансирования (КфВ) (грант) Фаза 2 | L10: =ROUND(COM!H10,1) -> #REF! | M10: =ROUND(COM!I10,1) -> #REF! | N10: =ROUND(COM!J10,1) -> #REF! | O10: =ROUND(COM!K10,1) -> #REF! | P10: =ROUND(COM!L10,1) -> #REF! | Q10: =ROUND(COM!M10,1) -> #REF! | R10: =ROUND(COM!N10,1) -> #REF! | S10: =ROUND(COM!O10,1) -> #REF! | ... W10: =ROUND(COM!S10,1) -> #REF! | X10: =M10+O10+Q10+S10+U10+W10 -> #REF!
A11: 311 | B11: 25 | C11: 910 | D11: 70499 | F11: Цепочка добавленной стоимости агрофинансирования-2 (ИФЦА) | L11: =ROUND(COM!H11,1) -> #REF! | M11: =ROUND(COM!I11,1) -> #REF! | N11: =ROUND(COM!J11,1) -> #REF! | O11: =ROUND(COM!K11,1) -> #REF! | P11: =ROUND(COM!L11,1) -> #REF! | Q11: =ROUND(COM!M11,1) -> #REF! | R11: =ROUND(COM!N11,1) -> #REF! | S11: =ROUND(COM!O11,1) -> #REF! | ... W11: =ROUND(COM!S11,1) -> #REF! | X11: =M11+O11+Q11+S11+U11+W11 -> #REF!
A12: 311 | B12: 25 | C12: 920 | D12: 70499 | E12: ИФЦА | F12: Цепочка добавленной стоимости агрофинансирования-2 (ИФЦА) (грант) | L12: =ROUND(COM!H12,1) -> #REF! | M12: =ROUND(COM!I12,1) -> #REF! | N12: =ROUND(COM!J12,1) -> #REF! | O12: =ROUND(COM!K12,1) -> #REF! | P12: =ROUND(COM!L12,1) -> #REF! | Q12: =ROUND(COM!M12,1) -> #REF! | R12: =ROUND(COM!N12,1) -> #REF! | S12: =ROUND(COM!O12,1) -> #REF! | ... W12: =ROUND(COM!S12,1) -> #REF! | X12: =M12+O12+Q12+S12+U12+W12 -> #REF!
A13: 321 | B13: 25 | C13: 930 | D13: 70499 | E13: ЕИБ | F13: Цепочка добавленной стоимости агрофинансирования-2 (ЕИБ) (кредит) | G13: FI № 84.373 | L13: =ROUND(COM!H13,1) -> #REF! | M13: =ROUND(COM!I13,1) -> #REF! | N13: =ROUND(COM!J13,1) -> #REF! | O13: =ROUND(COM!K13,1) -> #REF! | P13: =ROUND(COM!L13,1) -> #REF! | Q13: =ROUND(COM!M13,1) -> #REF! | R13: =ROUND(COM!N13,1) -> #REF! | S13: =ROUND(COM!O13,1) -> #REF! | ... W13: =ROUND(COM!S13,1) -> #REF! | X13: =M13+O13+Q13+S13+U13+W13 -> #REF!
A14: 311 | B14: 25 | C14: 920 | D14: 70499 | E14: ВБ | F14: Комплексное повышение производительности молочного сектора (ВБ) (грант) Доп. Финансирование | L14: =ROUND(COM!H14,1) -> #REF! | M14: =ROUND(COM!I14,1) -> #REF! | N14: =ROUND(COM!J14,1) -> #REF! | O14: =ROUND(COM!K14,1) -> #REF! | P14: =ROUND(COM!L14,1) -> #REF! | Q14: =ROUND(COM!M14,1) -> #REF! | R14: =ROUND(COM!N14,1) -> #REF! | S14: =ROUND(COM!O14,1) -> #REF! | ... W14: =ROUND(COM!S14,1) -> #REF! | X14: =M14+O14+Q14+S14+U14+W14 -> #REF!
A15: 321 | B15: 25 | C15: 920 | D15: 70499 | E15: ВБ | F15: Комплексное повышение производительности молочного сектора (ВБ) (грант) Доп. Финансирование | L15: =ROUND(COM!H15,1) -> #REF! | M15: =ROUND(COM!I15,1) -> #REF! | N15: =ROUND(COM!J15,1) -> #REF! | O15: =ROUND(COM!K15,1) -> #REF! | P15: =ROUND(COM!L15,1) -> #REF! | Q15: =ROUND(COM!M15,1) -> #REF! | R15: =ROUND(COM!N15,1) -> #REF! | S15: =ROUND(COM!O15,1) -> #REF! | ... W15: =ROUND(COM!S15,1) -> #REF! | X15: =M15+O15+Q15+S15+U15+W15 -> #REF!
A16: 311 | B16: 25 | C16: 930 | D16: 70499 | E16: ВБ | F16: Комплексное повышение производительности молочного сектора (ВБ) (кредит) Доп. Финансирование | G16: № 6941-KG | L16: =ROUND(COM!H16,1) -> #REF! | M16: =ROUND(COM!I16,1) -> #REF! | N16: =ROUND(COM!J16,1) -> #REF! | O16: =ROUND(COM!K16,1) -> #REF! | P16: =ROUND(COM!L16,1) -> #REF! | Q16: =ROUND(COM!M16,1) -> #REF! | R16: =ROUND(COM!N16,1) -> #REF! | S16: =ROUND(COM!O16,1) -> #REF! | ... W16: =ROUND(COM!S16,1) -> #REF! | X16: =M16+O16+Q16+S16+U16+W16 -> #REF!
A17: 321 | B17: 25 | C17: 930 | D17: 70499 | E17: ВБ | F17: Комплексное повышение производительности молочного сектора (ВБ) (кредит) Доп. Финансирование | L17: =ROUND(COM!H17,1) -> #REF! | M17: =ROUND(COM!I17,1) -> #REF! | N17: =ROUND(COM!J17,1) -> #REF! | O17: =ROUND(COM!K17,1) -> #REF! | P17: =ROUND(COM!L17,1) -> #REF! | Q17: =ROUND(COM!M17,1) -> #REF! | R17: =ROUND(COM!N17,1) -> #REF! | S17: =ROUND(COM!O17,1) -> #REF! | ... W17: =ROUND(COM!S17,1) -> #REF! | X17: =M17+O17+Q17+S17+U17+W17 -> #REF!
A18: 311 | B18: 25 | C18: 920 | D18: 70499 | E18: ВБ | F18: Проект по поддержке частного сектора (ВБ) (грант) | L18: =ROUND(COM!H18,1) -> #REF! | M18: =ROUND(COM!I18,1) -> #REF! | N18: =ROUND(COM!J18,1) -> #REF! | O18: =ROUND(COM!K18,1) -> #REF! | P18: =ROUND(COM!L18,1) -> #REF! | Q18: =ROUND(COM!M18,1) -> #REF! | R18: =ROUND(COM!N18,1) -> #REF! | S18: =ROUND(COM!O18,1) -> #REF! | ... W18: =ROUND(COM!S18,1) -> #REF! | X18: =M18+O18+Q18+S18+U18+W18 -> #REF!
A19: 321 | B19: 25 | C19: 920 | D19: 70499 | E19: ВБ | F19: Проект по поддержке частного сектора (ВБ) (грант) | L19: =ROUND(COM!H19,1) -> #REF! | M19: =ROUND(COM!I19,1) -> #REF! | N19: =ROUND(COM!J19,1) -> #REF! | O19: =ROUND(COM!K19,1) -> #REF! | P19: =ROUND(COM!L19,1) -> #REF! | Q19: =ROUND(COM!M19,1) -> #REF! | R19: =ROUND(COM!N19,1) -> #REF! | S19: =ROUND(COM!O19,1) -> #REF! | ... W19: =ROUND(COM!S19,1) -> #REF! | X19: =M19+O19+Q19+S19+U19+W19 -> #REF!
A20: 321 | B20: 25 | C20: 930 | D20: 70499 | E20: ВБ | F20: Проект по поддержке частного сектора (ВБ) (кредит) | G20: № 6758-KG | L20: =ROUND(COM!H20,1) -> #REF! | M20: =ROUND(COM!I20,1) -> #REF! | N20: =ROUND(COM!J20,1) -> #REF! | O20: =ROUND(COM!K20,1) -> #REF! | P20: =ROUND(COM!L20,1) -> #REF! | Q20: =ROUND(COM!M20,1) -> #REF! | R20: =ROUND(COM!N20,1) -> #REF! | S20: =ROUND(COM!O20,1) -> #REF! | ... W20: =ROUND(COM!S20,1) -> #REF! | X20: =M20+O20+Q20+S20+U20+W20 -> #REF!
A21: 311 | B21: 25 | C21: 930 | D21: 70499 | E21: АБИИ | F21: Проект по поддержке частного сектора (АБИИ) (кредит) | G21: № 0423-А | L21: =ROUND(COM!H21,1) -> #REF! | M21: =ROUND(COM!I21,1) -> #REF! | N21: =ROUND(COM!J21,1) -> #REF! | O21: =ROUND(COM!K21,1) -> #REF! | P21: =ROUND(COM!L21,1) -> #REF! | Q21: =ROUND(COM!M21,1) -> #REF! | R21: =ROUND(COM!N21,1) -> #REF! | S21: =ROUND(COM!O21,1) -> #REF! | ... W21: =ROUND(COM!S21,1) -> #REF! | X21: =M21+O21+Q21+S21+U21+W21 -> #REF!
A22: 321 | B22: 25 | C22: 930 | D22: 70499 | E22: АБИИ | F22: Проект по поддержке частного сектора (АБИИ) (кредит) | L22: =ROUND(COM!H22,1) -> #REF! | M22: =ROUND(COM!I22,1) -> #REF! | N22: =ROUND(COM!J22,1) -> #REF! | O22: =ROUND(COM!K22,1) -> #REF! | P22: =ROUND(COM!L22,1) -> #REF! | Q22: =ROUND(COM!M22,1) -> #REF! | R22: =ROUND(COM!N22,1) -> #REF! | S22: =ROUND(COM!O22,1) -> #REF! | ... W22: =ROUND(COM!S22,1) -> #REF! | X22: =M22+O22+Q22+S22+U22+W22 -> #REF!
A23: 311 | B23: 25 | C23: 920 | D23: 70499 | E23: ВБ | F23: Экстренная поддержка микро, малых и средних предприятий ДФ (ВБ) (грант) | L23: =ROUND(COM!H23,1) -> #REF! | M23: =ROUND(COM!I23,1) -> #REF! | N23: =ROUND(COM!J23,1) -> #REF! | O23: =ROUND(COM!K23,1) -> #REF! | P23: =ROUND(COM!L23,1) -> #REF! | Q23: =ROUND(COM!M23,1) -> #REF! | R23: =ROUND(COM!N23,1) -> #REF! | S23: =ROUND(COM!O23,1) -> #REF! | ... W23: =ROUND(COM!S23,1) -> #REF! | X23: =M23+O23+Q23+S23+U23+W23 -> #REF!
A24: 321 | B24: 25 | C24: 920 | D24: 70499 | E24: ВБ | F24: Экстренная поддержка микро, малых и средних предприятий ДФ (ВБ) (грант) | L24: =ROUND(COM!H24,1) -> #REF! | M24: =ROUND(COM!I24,1) -> #REF! | N24: =ROUND(COM!J24,1) -> #REF! | O24: =ROUND(COM!K24,1) -> #REF! | P24: =ROUND(COM!L24,1) -> #REF! | Q24: =ROUND(COM!M24,1) -> #REF! | R24: =ROUND(COM!N24,1) -> #REF! | S24: =ROUND(COM!O24,1) -> #REF! | ... W24: =ROUND(COM!S24,1) -> #REF! | X24: =M24+O24+Q24+S24+U24+W24 -> #REF!
A25: 321 | B25: 25 | C25: 930 | D25: 70499 | E25: ВБ | F25: Экстренная поддержка микро, малых и средних предприятий ДФ (ВБ) (кредит) | G25: № 7094-KG | L25: =ROUND(COM!H25,1) -> #REF! | M25: =ROUND(COM!I25,1) -> #REF! | N25: =ROUND(COM!J25,1) -> #REF! | O25: =ROUND(COM!K25,1) -> #REF! | P25: =ROUND(COM!L25,1) -> #REF! | Q25: =ROUND(COM!M25,1) -> #REF! | R25: =ROUND(COM!N25,1) -> #REF! | S25: =ROUND(COM!O25,1) -> #REF! | ... W25: =ROUND(COM!S25,1) -> #REF! | X25: =M25+O25+Q25+S25+U25+W25 -> #REF!
A26: 311 | B26: 25 | C26: 930 | D26: 70499 | E26: ВБ | F26: Улучшение качества воздуха в городе Бишкек (ВБ) (кредит) | G26: № 7434-KG | L26: =ROUND(COM!H26,1) -> #REF! | M26: =ROUND(COM!I26,1) -> #REF! | N26: =ROUND(COM!J26,1) -> #REF! | O26: =ROUND(COM!K26,1) -> #REF! | P26: =ROUND(COM!L26,1) -> #REF! | Q26: =ROUND(COM!M26,1) -> #REF! | R26: =ROUND(COM!N26,1) -> #REF! | S26: =ROUND(COM!O26,1) -> #REF! | ... W26: =ROUND(COM!S26,1) -> #REF! | X26: =M26+O26+Q26+S26+U26+W26 -> #REF!
A27: 321 | B27: 25 | C27: 930 | D27: 70499 | E27: ВБ | F27: Улучшение качества воздуха в городе Бишкек (ВБ) (кредит) | L27: =ROUND(COM!H27,1) -> #REF! | M27: =ROUND(COM!I27,1) -> #REF! | N27: =ROUND(COM!J27,1) -> #REF! | O27: =ROUND(COM!K27,1) -> #REF! | P27: =ROUND(COM!L27,1) -> #REF! | Q27: =ROUND(COM!M27,1) -> #REF! | R27: =ROUND(COM!N27,1) -> #REF! | S27: =ROUND(COM!O27,1) -> #REF! | ... W27: =ROUND(COM!S27,1) -> #REF! | X27: =M27+O27+Q27+S27+U27+W27 -> #REF!
A28: 311 | B28: 25 | C28: 930 | D28: 70499 | E28: ВБ | F28: Проект развития устойчивых агропродовольственных кластеров (ВБ) (кредит) | G28: № 7526-KG | L28: =ROUND(COM!H28,1) -> #REF! | M28: =ROUND(COM!I28,1) -> #REF! | N28: =ROUND(COM!J28,1) -> #REF! | O28: =ROUND(COM!K28,1) -> #REF! | P28: =ROUND(COM!L28,1) -> #REF! | Q28: =ROUND(COM!M28,1) -> #REF! | R28: =ROUND(COM!N28,1) -> #REF! | S28: =ROUND(COM!O28,1) -> #REF! | ... W28: =ROUND(COM!S28,1) -> #REF! | X28: =M28+O28+Q28+S28+U28+W28 -> #REF!
A29: 321 | B29: 25 | C29: 930 | D29: 70499 | E29: ВБ | F29: Проект развития устойчивых агропродовольственных кластеров (ВБ) (кредит) | L29: =ROUND(COM!H29,1) -> #REF! | M29: =ROUND(COM!I29,1) -> #REF! | N29: =ROUND(COM!J29,1) -> #REF! | O29: =ROUND(COM!K29,1) -> #REF! | P29: =ROUND(COM!L29,1) -> #REF! | Q29: =ROUND(COM!M29,1) -> #REF! | R29: =ROUND(COM!N29,1) -> #REF! | S29: =ROUND(COM!O29,1) -> #REF! | ... W29: =ROUND(COM!S29,1) -> #REF! | X29: =M29+O29+Q29+S29+U29+W29 -> #REF!
A30: 311 | B30: 25 | C30: 930 | D30: 70499 | E30: ВБ | F30: Развитие устойчивых финансовых рынков для микро-, малых и средних предприятий в Кыргызской Республике (ВБ) (кредит) (план) | G30: 7741-KG | L30: =ROUND(COM!H30,1) -> #REF! | M30: =ROUND(COM!I30,1) -> #REF! | N30: =ROUND(COM!J30,1) -> #REF! | O30: =ROUND(COM!K30,1) -> #REF! | P30: =ROUND(COM!L30,1) -> #REF! | Q30: =ROUND(COM!M30,1) -> #REF! | R30: =ROUND(COM!N30,1) -> #REF! | S30: =ROUND(COM!O30,1) -> #REF! | ... W30: =ROUND(COM!S30,1) -> #REF! | X30: =M30+O30+Q30+S30+U30+W30 -> #REF!
A31: 321 | B31: 25 | C31: 930 | D31: 70499 | E31: ВБ | F31: Развитие устойчивых финансовых рынков для микро-, малых и средних предприятий в Кыргызской Республике (ВБ) (кредит) (план) | L31: =ROUND(COM!H31,1) -> #REF! | M31: =ROUND(COM!I31,1) -> #REF! | N31: =ROUND(COM!J31,1) -> #REF! | O31: =ROUND(COM!K31,1) -> #REF! | P31: =ROUND(COM!L31,1) -> #REF! | Q31: =ROUND(COM!M31,1) -> #REF! | R31: =ROUND(COM!N31,1) -> #REF! | S31: =ROUND(COM!O31,1) -> #REF! | ... W31: =ROUND(COM!S31,1) -> #REF! | X31: =M31+O31+Q31+S31+U31+W31 -> #REF!
A32: 311 | B32: 25 | C32: 920 | D32: 70499 | E32: ВБ | F32: Проект сельских инвестиций - 3 ДФ (ВБ) (грант) | L32: =ROUND(COM!H32,1) -> #REF! | M32: =ROUND(COM!I32,1) -> #REF! | N32: =ROUND(COM!J32,1) -> #REF! | O32: =ROUND(COM!K32,1) -> #REF! | P32: =ROUND(COM!L32,1) -> #REF! | Q32: =ROUND(COM!M32,1) -> #REF! | R32: =ROUND(COM!N32,1) -> #REF! | S32: =ROUND(COM!O32,1) -> #REF! | ... W32: =ROUND(COM!S32,1) -> #REF!
A33: 311 | B33: 25 | C33: 930 | D33: 70499 | E33: ВБ | F33: Проект сельских инвестиций - 3 ДФ (ВБ) (кредит) | L33: =ROUND(COM!H33,1) -> #REF! | M33: =ROUND(COM!I33,1) -> #REF! | N33: =ROUND(COM!J33,1) -> #REF! | O33: =ROUND(COM!K33,1) -> #REF! | P33: =ROUND(COM!L33,1) -> #REF! | Q33: =ROUND(COM!M33,1) -> #REF! | R33: =ROUND(COM!N33,1) -> #REF! | S33: =ROUND(COM!O33,1) -> #REF! | ... W33: =ROUND(COM!S33,1) -> #REF!
X34: =M34+O34+Q34+S34+U34+W34 -> 0
X36: =M36+O36+Q36+S36+U36+W36 -> 0
X37: =M37+O37+Q37+S37+U37+W37 -> 0
X38: =M38+O38+Q38+S38+U38+W38 -> 0
F39: Министерство экономики и коммерции КР | L39: =L40 -> #REF! | M39: =M40 -> #REF! | N39: =N40 -> #REF! | O39: =O40 -> #REF! | P39: =P40 -> #REF! | Q39: =Q40 -> #REF! | R39: =R40 -> #REF! | S39: =S40 -> #REF! | ... W39: =W40 -> #REF! | X39: =M39+O39+Q39+S39+U39+W39 -> #REF!
F40: Государственные инвестиции | L40: =SUM(L41:L68) -> #REF! | M40: =SUM(M41:M68) -> #REF! | N40: =SUM(N41:N68) -> #REF! | O40: =SUM(O41:O68) -> #REF! | P40: =SUM(P41:P68) -> #REF! | Q40: =SUM(Q41:Q68) -> #REF! | R40: =SUM(R41:R68) -> #REF! | S40: =SUM(S41:S68) -> #REF! | ... W40: =SUM(W41:W68) -> #REF! | X40: =M40+O40+Q40+S40+U40+W40 -> #REF!
A41: 311 | B41: 28 | C41: 920 | D41: 70499 | E41: ВБ | F41: Проект регионального экономического развития Ошской области (ВБ) (грант) | G41: Грант D5700-KG/Кредит 6558-KG | L41: =ROUND(COM!H41,1) -> #REF! | M41: =ROUND(COM!I41,1) -> #REF! | N41: =ROUND(COM!J41,1) -> #REF! | O41: =ROUND(COM!K41,1) -> #REF! | P41: =ROUND(COM!L41,1) -> #REF! | Q41: =ROUND(COM!M41,1) -> #REF! | R41: =ROUND(COM!N41,1) -> #REF! | S41: =ROUND(COM!O41,1) -> #REF! | ... W41: =ROUND(COM!S41,1) -> #REF! | X41: =M41+O41+Q41+S41+U41+W41 -> #REF!
A42: 311 | B42: 28 | C42: 930 | D42: 70499 | E42: ВБ | F42: Проект регионального экономического развития Ошской области (ВБ) (кредит) | L42: =ROUND(COM!H42,1) -> #REF! | M42: =ROUND(COM!I42,1) -> #REF! | N42: =ROUND(COM!J42,1) -> #REF! | O42: =ROUND(COM!K42,1) -> #REF! | P42: =ROUND(COM!L42,1) -> #REF! | Q42: =ROUND(COM!M42,1) -> #REF! | R42: =ROUND(COM!N42,1) -> #REF! | S42: =ROUND(COM!O42,1) -> #REF! | ... W42: =ROUND(COM!S42,1) -> #REF! | X42: =M42+O42+Q42+S42+U42+W42 -> #REF!
A43: 311 | B43: 28 | C43: 930 | D43: 70499 | E43: ВБ | F43: Проект регионального экономического развития Ошской области - дополнительное финансирование (ВБ) (кредит) | L43: =ROUND(COM!H43,1) -> #REF! | M43: =ROUND(COM!I43,1) -> #REF! | N43: =ROUND(COM!J43,1) -> #REF! | O43: =ROUND(COM!K43,1) -> #REF! | P43: =ROUND(COM!L43,1) -> #REF! | Q43: =ROUND(COM!M43,1) -> #REF! | R43: =ROUND(COM!N43,1) -> #REF! | S43: =ROUND(COM!O43,1) -> #REF! | ... W43: =ROUND(COM!S43,1) -> #REF! | X43: =M43+O43+Q43+S43+U43+W43 -> #REF!
A44: 311 | B44: 28 | C44: 920 | D44: 70499 | E44: ВБ | F44: Проект регионального экономического развития Баткенской области (ВБ) (грант) | G44: Грант D976-KG/Кредит 70490-KG | L44: =ROUND(COM!H44,1) -> #REF! | M44: =ROUND(COM!I44,1) -> #REF! | N44: =ROUND(COM!J44,1) -> #REF! | O44: =ROUND(COM!K44,1) -> #REF! | P44: =ROUND(COM!L44,1) -> #REF! | Q44: =ROUND(COM!M44,1) -> #REF! | R44: =ROUND(COM!N44,1) -> #REF! | S44: =ROUND(COM!O44,1) -> #REF! | ... W44: =ROUND(COM!S44,1) -> #REF! | X44: =M44+O44+Q44+S44+U44+W44 -> #REF!
...
